Workbook

Sheet DASHBOARD
A1: TOP LEISURE -INVESTMENT APPRISAL
I8: Overview - | J8: Investment appraisal to investigate if this project will generate more money than | P8: Capital Structure - | Q8: Capital strucutre forms an important part in understanding what is the WACC which is used for
J9: what the initial investment. | Q9: calculating the value which this project will generate.
I10: WACC - | J10: Based on external benchmark for established leisure group, 8% to 10% is a fair | P10: Local Area - | Q10: It is important to know in which area are these sites operating as the local area has a impact
E11: Base Case | F11: Scenario | J11: assumption. Considering Top Leisure's strong market position, 8% is a fair | Q11: on the cashflow and the risk premium in calculating the cost of equity.
J12: assumption. | P12: Business Rates - | Q12: As we are working with the authority will we have any rebate in the business rates?
I13: Gainshare - | J13: The operator pays the authority based on three-year rolling return. Reward to the | P13: Gainshare - | Q13: How does the reward for the operator work?
J14: operator from authority is ignored. | P14: Reward Contracts - | Q14: Rewards to the operator have been ignored as need more information to understand the
E15: 0 | F15: Delay in project by years | I15: Early Years - | J15: The model assumes early years to be the first three years. | Q15: structure of rewards and how do they operate.
I16: Expenditure - | J16: The perating expenditure is assumed to increased by 2.5% each year to reflect inflation. | P16: Borrowing Costs - | Q16: Details on borrowing costs to understand the covenants in case if they impact free cashflow.
J17: These expenses are broken down as - Staff Cost 45%, Utilities 25%, R&M 25%, | P17: Management Fee - | Q17: Details on indexation rules, fee calculation formula and timelines on fixed fee structures.
J18: Other operating expenditures 10% | P18: Non Financial Risk - | Q18: Authority's past behaviour in similar contracts, any budgetary pressures and their risk appetite.
E19: 0.08 | F19: WACC | I19: Capex - | J19: In year 10 and year 18, additional capex expenditure is projected as these sites will | P19: Capex Details - | Q19: Timing and phasing of £9.62m initial investment. Maintenance obligation and lifestyle cost expectations.
J20: need some maintenance of capital in nature.
I21: Revenue Weights - | J21: Revenue contributions are weighted with the new site as the higest contibutor,
J22: followed by the smaller site, and then the golf centre.
I23: Borrowing Costs - | J23: Have increased by 1% each year. | P23: Based on the financial modelling and available information, I would recommend investing in this project, only if timing and
I24: Scenarios - | J24: Base Case £116m, Worst Case £161m, Best Case £173m. | P24: liqudity risks are mitigated or unless it offers strategic value or clear synergies with the wider group.
P26: In the base case, the project starts generating surplus cash only after year 5, and requires up to £7m in liquidity beyond the
P27: initial investment. This assumes the project is delivered on time. If the project is delayed by just one year surplus cash is pushed
I28: NPV - Net present Value. It is the value today of all future net cashflows after covering the investment cost. | P28: back to year 8, and the liquidity requirement rises to £11m. (Cashflow investment journey graph)
I29: IRR - Internal Rate of Return, tells us the project's return. If it does not beat our cost of capital, it's not worth.
I30: WACC - Weighted average cost of capital, the blended average cost of the debt and equity we use to fund | P30: In the worst-case scenario, the IRR drops to 13%, which is above the discount rate (WACC of 8%) but not compelling given the
I31: this project | P31: operational and financial risk. If the worst-case scenario includes a one-year delay, the project generates negative NPV,
I32: Cashflow investment journey graph - Shows at what point does the project start generating surplus cash. | P32: meaning it would destroy value for Top Leisure in monetary terms.
A34: IRR | B34: =IRR('Opreating Cashflow'!B36:U36) -> 0.1720889 | P34: Overall, the project appears financially fragile with limited upside, but could be strengthened through focused management
P35: of timing and delivery risks.

Sheet Opreating Cashflow
A1: Descriptions | B1: =+Data!B8 -> Year1 | C1: =+Data!C8 -> Year2 | D1: =+Data!D8 -> Year3 | E1: =+Data!E8 -> Year4 | F1: =+Data!F8 -> Year5 | G1: =+Data!G8 -> Year6 | H1: =+Data!H8 -> Year7 | I1: =+Data!I8 -> Year8 | ... U1: =+Data!U8 -> Year20
A3: REVENUE
A4: Interim Facility Revenue | B4: =+Data!B26/1000 -> 5596.5 | C4: =+Data!C26/1000 -> 5596.5 | D4: =+Data!D26/1000 -> 0 | E4: =+Data!E26/1000 -> 0 | F4: =+Data!F26/1000 -> 0 | G4: =+Data!G26/1000 -> 0 | H4: =+Data!H26/1000 -> 0 | I4: =+Data!I26/1000 -> 0 | ... U4: =+Data!U26/1000 -> 0
A5: New flagship Revenue | B5: =+Data!B27/1000 -> 0 | C5: =+Data!C27/1000 -> 0 | D5: =+Data!D27/1000 -> 5036.5 | E5: =+Data!E27/1000 -> 5036.5 | F5: =+Data!F27/1000 -> 5036.5 | G5: =+Data!G27/1000 -> 5137.23 | H5: =+Data!H27/1000 -> 5239.9746 | I5: =+Data!I27/1000 -> 5344.7741 | ... U5: =+Data!U27/1000 -> 7187.1007
A6: Health & Fitness (Small) | B6: =+Data!B28/1000 -> 2152.5 | C6: =+Data!C28/1000 -> 2152.5 | D6: =+Data!D28/1000 -> 2152.5 | E6: =+Data!E28/1000 -> 2152.5 | F6: =+Data!F28/1000 -> 2152.5 | G6: =+Data!G28/1000 -> 2152.5 | H6: =+Data!H28/1000 -> 2152.5 | I6: =+Data!I28/1000 -> 2152.5 | ... U6: =+Data!U28/1000 -> 0
A7: Golf Centre | B7: =+Data!B29/1000 -> 861 | C7: =+Data!C29/1000 -> 861 | D7: =+Data!D29/1000 -> 861 | E7: =+Data!E29/1000 -> 861 | F7: =+Data!F29/1000 -> 861 | G7: =+Data!G29/1000 -> 861 | H7: =+Data!H29/1000 -> 861 | I7: =+Data!I29/1000 -> 861 | ... U7: =+Data!U29/1000 -> 861
A8: TOTAL REVENUE | B8: =SUM(B4:B7) -> 8610 | C8: =SUM(C4:C7) -> 8610 | D8: =SUM(D4:D7) -> 8050 | E8: =SUM(E4:E7) -> 8050 | F8: =SUM(F4:F7) -> 8050 | G8: =SUM(G4:G7) -> 8150.73 | H8: =SUM(H4:H7) -> 8253.4746 | I8: =SUM(I4:I7) -> 8358.2741 | ... U8: =SUM(U4:U7) -> 8048.1007
A11: OPERATING EXPENDITURE
A12: Staff Cost | B12: =-Data!$B$37*VLOOKUP('Opreating Cashflow'!$A12,Data!$A$38:$B$41,2,0)/1000 -> -2686.5 | C12: =(+B12*(2.5%/4))+B12 -> -2703.2906 | D12: =(+C12*(2.5%/4))+C12 -> -2720.1862 | E12: =(+D12*(2.5%/4))+D12 -> -2737.1874 | F12: =(+E12*(2.5%/4))+E12 -> -2754.2948 | G12: =(+F12*(2.5%/4))+F12 -> -2771.5091 | H12: =(+G12*(2.5%/4))+G12 -> -2788.8311 | I12: =(+H12*(2.5%/4))+H12 -> -2806.2612 | J12: =(+I12*(2.5%/4))+I12 -> -2823.8004 | ... U12: =(+T12*(2.5%/4))+T12 -> -3024.1186
A13: Utilites | B13: =-Data!$B$37*VLOOKUP('Opreating Cashflow'!$A13,Data!$A$38:$B$41,2,0)/1000 -> -1492.5 | C13: =(+B13*(2.5%/4))+B13 -> -1501.8281 | D13: =(+C13*(2.5%/4))+C13 -> -1511.2146 | E13: =(+D13*(2.5%/4))+D13 -> -1520.6596 | F13: =(+E13*(2.5%/4))+E13 -> -1530.1638 | G13: =(+F13*(2.5%/4))+F13 -> -1539.7273 | H13: =(+G13*(2.5%/4))+G13 -> -1549.3506 | I13: =(+H13*(2.5%/4))+H13 -> -1559.034 | J13: =(+I13*(2.5%/4))+I13 -> -1568.778 | ... U13: =(+T13*(2.5%/4))+T13 -> -1680.0659
A14: Repairs & Maintenance | B14: =-Data!$B$37*VLOOKUP('Opreating Cashflow'!$A14,Data!$A$38:$B$41,2,0)/1000 -> -1194 | C14: =(+B14*(2.5%/4))+B14 -> -1201.4625 | D14: =(+C14*(2.5%/4))+C14 -> -1208.9716 | E14: =(+D14*(2.5%/4))+D14 -> -1216.5277 | F14: =(+E14*(2.5%/4))+E14 -> -1224.131 | G14: =(+F14*(2.5%/4))+F14 -> -1231.7818 | H14: =(+G14*(2.5%/4))+G14 -> -1239.4805 | I14: =(+H14*(2.5%/4))+H14 -> -1247.2272 | J14: =(+I14*(2.5%/4))+I14 -> -1255.0224 | ... U14: =(+T14*(2.5%/4))+T14 -> -1344.0527
A15: Other opex | B15: =-Data!$B$37*VLOOKUP('Opreating Cashflow'!$A15,Data!$A$38:$B$41,2,0)/1000 -> -597 | C15: =(+B15*(2.5%/4))+B15 -> -600.73125 | D15: =(+C15*(2.5%/4))+C15 -> -604.48582 | E15: =(+D15*(2.5%/4))+D15 -> -608.26386 | F15: =(+E15*(2.5%/4))+E15 -> -612.06551 | G15: =(+F15*(2.5%/4))+F15 -> -615.89092 | H15: =(+G15*(2.5%/4))+G15 -> -619.74023 | I15: =(+H15*(2.5%/4))+H15 -> -623.61361 | J15: =(+I15*(2.5%/4))+I15 -> -627.51119 | ... U15: =(+T15*(2.5%/4))+T15 -> -672.02636
A16: TOTAL OPERATING EXPENDITURE | B16: =SUM(B12:B15) -> -5970 | C16: =SUM(C12:C15) -> -6007.3125 | D16: =SUM(D12:D15) -> -6044.8582 | E16: =SUM(E12:E15) -> -6082.6386 | F16: =SUM(F12:F15) -> -6120.6551 | G16: =SUM(G12:G15) -> -6158.9092 | H16: =SUM(H12:H15) -> -6197.4023 | I16: =SUM(I12:I15) -> -6236.1361 | ... U16: =SUM(U12:U15) -> -6720.2636
A18: Depreciation | B18: =-630000/1000 -> -630 | C18: =-630000/1000 -> -630 | D18: =-630000/1000 -> -630 | E18: =-630000/1000 -> -630 | F18: =-630000/1000 -> -630 | G18: =-630000/1000 -> -630 | H18: =-630000/1000 -> -630 | I18: =-630000/1000 -> -630 | ... U18: =-630000/1000 -> -630
A19: Borrowing Cost | B19: =-170000/1000 -> -170 | C19: =+B19*1.01 -> -171.7 | D19: =+C19*1.01 -> -173.417 | E19: =+D19*1.01 -> -175.15117 | F19: =+E19*1.01 -> -176.90268 | G19: =+F19*1.01 -> -178.67171 | H19: =+G19*1.01 -> -180.45843 | I19: =+H19*1.01 -> -182.26301 | J19: =+I19*1.01 -> -184.08564 | ... U19: =+T19*1.01 -> -205.37852
A20: Total Non-Operating EXPENDITURE | B20: =+B18+B19 -> -800 | C20: =+C18+C19 -> -801.7 | D20: =+D18+D19 -> -803.417 | E20: =+E18+E19 -> -805.15117 | F20: =+F18+F19 -> -806.90268 | G20: =+G18+G19 -> -808.67171 | H20: =+H18+H19 -> -810.45843 | I20: =+I18+I19 -> -812.26301 | ... U20: =+U18+U19 -> -835.37852
A22: OPERATING SURPLUS | B22: =+B8+B16+B20 -> 1840 | C22: =+C8+C16+C20 -> 1800.9875 | D22: =+D8+D16+D20 -> 1201.7248 | E22: =+E8+E16+E20 -> 1162.2103 | F22: =+F8+F16+F20 -> 1122.4423 | G22: =+G8+G16+G20 -> 1183.1491 | H22: =+H8+H16+H20 -> 1245.6138 | I22: =+I8+I16+I20 -> 1309.875 | ... U22: =+U8+U16+U20 -> 492.45867
A24: Gainshare | D24: =IF(AVERAGE(B22:D22)>0,-50%*AVERAGE(B22:D22),0) -> -807.11872 | G24: =IF(AVERAGE(E22:G22)>0,-50%*AVERAGE(E22:G22),0) -> -577.96694 | J24: =IF(AVERAGE(H22:J22)>0,-50%*AVERAGE(H22:J22),0) -> -655.24347 | M24: =IF(AVERAGE(K22:M22)>0,-50%*AVERAGE(K22:M22),0) -> -757.24415 | P24: =IF(AVERAGE(N22:P22)>0,-50%*AVERAGE(N22:P22),0) -> -628.09617 | S24: =IF(AVERAGE(Q22:S22)>0,-50%*AVERAGE(Q22:S22),0) -> -224.94164
A25: Management Fee | B25: =-480000/1000 -> -480 | C25: =-480000/1000 -> -480 | D25: =-480000/1000 -> -480 | E25: 700 | F25: 700 | G25: 700 | H25: 700 | I25: 700 | J25: 700 | K25: 700 | L25: 700 | M25: 700 | N25: 700 | O25: 700 | P25: 700 | Q25: 700 | R25: 700 | S25: 700 | T25: 700 | U25: 700
A27: NET OPERATING CASHFLOW | B27: =+B22+B24+B25 -> 1360 | C27: =+C22+C24+C25 -> 1320.9875 | D27: =+D22+D24+D25 -> -85.393919 | E27: =+E22+E24+E25 -> 1862.2103 | F27: =+F22+F24+F25 -> 1822.4423 | G27: =+G22+G24+G25 -> 1305.1822 | H27: =+H22+H24+H25 -> 1945.6138 | I27: =+I22+I24+I25 -> 2009.875 | ... U27: =+U22+U24+U25 -> 1192.4587
A29: CAPITAL INVESTMENTS
A30: New leisure centre enhancements | B30: =((-8820000/1000))*0.65 -> -5733 | C30: =((-8820000/1000))*0.25 -> -2205 | D30: =((-8820000/1000))*0.1 -> -882 | K30: -400 | S30: -800
A31: Health & Fitness (Small) | B31: =-490000/1000 -> -490 | K31: -100 | S31: -200
A32: Golf Centre | B32: =-100000/1000 -> -100 | K32: -25 | S32: -50
A33: Interim Facility Revenue | B33: =-200000/1000 -> -200 | K33: -50 | S33: -75
A34: TOTAL CAPITAL INVESTMENTS | B34: =SUM(B30:B33) -> -6523 | C34: =SUM(C30:C33) -> -2205 | D34: =SUM(D30:D33) -> -882 | E34: =SUM(E30:E33) -> 0 | F34: =SUM(F30:F33) -> 0 | G34: =SUM(G30:G33) -> 0 | H34: =SUM(H30:H33) -> 0 | I34: =SUM(I30:I33) -> 0 | ... U34: =SUM(U30:U33) -> 0
A36: FREE CASHFLOW | B36: =+B27+B34 -> -5163 | C36: =+C27+C34 -> -884.0125 | D36: =+D27+D34 -> -967.39392 | E36: =+E27+E34 -> 1862.2103 | F36: =+F27+F34 -> 1822.4423 | G36: =+G27+G34 -> 1305.1822 | H36: =+H27+H34 -> 1945.6138 | I36: =+I27+I34 -> 2009.875 | ... U36: =+U27+U34 -> 1192.4587
A37: CUMULATIVE CASHFLOW | C37: =+B36+C36 -> -6047.0125 | D37: =+C37+D36 -> -7014.4064 | E37: =+D37+E36 -> -5152.1962 | F37: =+E37+F36 -> -3329.7539 | G37: =+F37+G36 -> -2024.5717 | H37: =+G37+H36 -> -78.95786 | I37: =+H37+I36 -> 1930.9171 | J37: =+I37+J36 -> 3351.6456 | K37: =+J37+K36 -> 4920.5907 | ... U37: =+T37+U36 -> 18222.414

Sheet Data
A1: No of Years | B1: 1 | C1: 2 | D1: 3 | E1: 4 | F1: 5 | G1: 6 | H1: 7 | I1: 8 | J1: 9 | K1: 10 | L1: 11 | M1: 12 | N1: 13 | O1: 14 | P1: 15 | Q1: 16 | R1: 17 | S1: 18 | T1: 19 | U1: 20
A2: Vlookup | B2: 2 | C2: 3 | D2: 4 | E2: 5 | F2: 6 | G2: 7 | H2: 8 | I2: 9 | J2: 10 | K2: 11 | L2: 12 | M2: 13 | N2: 14 | O2: 15 | P2: 16 | Q2: 17 | R2: 18 | S2: 19 | T2: 20 | U2: 21
A3: Sensitivity | B3: =+DASHBOARD!E11 -> Base Case
A4: Base Case | B4: 8610000
A5: Worst Case | B5: 8050000
A6: Best Case | B6: 9250000
B8: =CONCATENATE("Year","",B1) -> Year1 | C8: =CONCATENATE("Year","",C1) -> Year2 | D8: =CONCATENATE("Year","",D1) -> Year3 | E8: =CONCATENATE("Year","",E1) -> Year4 | F8: =CONCATENATE("Year","",F1) -> Year5 | G8: =CONCATENATE("Year","",G1) -> Year6 | H8: =CONCATENATE("Year","",H1) -> Year7 | I8: =CONCATENATE("Year","",I1) -> Year8 | ... U8: =CONCATENATE("Year","",U1) -> Year20
A9: Interim Facility Revenue | B9: 0.65 | C9: 0.65
A10: New flagship Revenue | D10: 0.65 | E10: 0.65 | F10: 0.65 | G10: 0.7 | H10: 0.7 | I10: 0.7 | J10: 0.75 | K10: 0.75 | L10: 0.75 | M10: 0.75 | N10: 0.8 | O10: 0.8 | P10: 0.8 | Q10: 0.85 | R10: 0.85 | S10: 0.85 | T10: 0.85 | U10: 0.85
A11: Health & Fitness (Small) | B11: 0.2 | C11: 0.2 | D11: 0.2 | E11: 0.2 | F11: 0.2 | G11: 0.15 | H11: 0.15 | I11: 0.15 | J11: 0.1 | K11: 0.1 | L11: 0.1 | M11: 0.1 | N11: 0.05 | O11: 0.05 | P11: 0.05 | Q11: 0 | R11: 0 | S11: 0 | T11: 0 | U11: 0
A12: Golf Centre | B12: 0.15 | C12: 0.15 | D12: 0.15 | E12: 0.15 | F12: 0.15 | G12: 0.15 | H12: 0.15 | I12: 0.15 | J12: 0.15 | K12: 0.15 | L12: 0.15 | M12: 0.15 | N12: 0.15 | O12: 0.15 | P12: 0.15 | Q12: 0.15 | R12: 0.15 | S12: 0.15 | T12: 0.15 | U12: 0.15
A14: Revenue
A15: Base Case | B15: 8610000 | C15: 8610000 | D15: 8050000 | E15: 8050000 | F15: 8050000 | G15: 8150730 | H15: 8253474.6 | I15: 8358274.1 | J15: 8465169.6 | K15: 8574203 | L15: 8685417 | M15: 8798855.4 | N15: 8914562.5 | O15: 8532583.7 | P15: 8213156.2 | Q15: 7899145.9 | R15: 8090715.3 | S15: 7635531.8 | T15: 7838767.7 | U15: 8048100.7 | V15: =SUM(B15:U15) -> 1.6582869e+08
A16: Worst Case | B16: 8050000 | C16: 8050000 | D16: 8050000 | E16: 8050000 | F16: 8050000 | G16: 8050000 | H16: 8050000 | I16: 8050000 | J16: 8050000 | K16: 8050000 | L16: 8050000 | M16: 8050000 | N16: 8050000 | O16: 8050000 | P16: 8050000 | Q16: 8050000 | R16: 8050000 | S16: 8050000 | T16: 8050000 | U16: 8050000 | V16: =SUM(B16:U16) -> 161000000
A17: Best Case | B17: 8610000 | C17: 8610000 | D17: 8610000 | E17: =+D17 -> 8610000 | F17: =+E17 -> 8610000 | G17: =+F17*1.005 -> 8653050 | H17: =+G17 -> 8653050 | I17: =+H17 -> 8653050 | J17: =+I17 -> 8653050 | K17: =+J17 -> 8653050 | L17: =+K17 -> 8653050 | M17: =+L17 -> 8653050 | N17: =+M17 -> 8653050 | O17: =+N17 -> 8653050 | P17: =+O17*1.005 -> 8696315.2 | Q17: =+P17 -> 8696315.2 | R17: =+Q17 -> 8696315.2 | S17: =+R17 -> 8696315.2 | T17: =+S17 -> 8696315.2 | U17: =+T17 -> 8696315.2 | V17: =SUM(B17:U17) -> 1.7310534e+08
A20: Interim Facility Revenue | B20: 0.65 | C20: 0.65 | D20: 0 | E20: 0 | F20: 0 | G20: 0 | H20: 0 | I20: 0 | J20: 0 | K20: 0 | L20: 0 | M20: 0 | N20: 0 | O20: 0 | P20: 0 | Q20: 0 | R20: 0 | S20: 0 | T20: 0 | U20: 0
A21: New flagship Revenue | B21: 0 | C21: 0 | D21: 0.62565217 | E21: 0.62565217 | F21: 0.62565217 | G21: 0.63027851 | H21: 0.63488105 | I21: 0.63945906 | J21: 0.64401186 | K21: 0.64853876 | L21: 0.65303911 | M21: 0.65751227 | N21: 0.66195761 | O21: 0.70542334 | P21: 0.75484455 | Q21: 0.80839701 | R21: 0.81293372 | S21: 0.88723772 | T21: 0.89016131 | U21: 0.89301824
A22: Health & Fitness (Small) | B22: 0.25 | C22: 0.25 | D22: 0.2673913 | E22: 0.2673913 | F22: 0.2673913 | G22: 0.26408678 | H22: 0.26079925 | I22: 0.25752924 | J22: 0.25427725 | K22: 0.25104374 | L22: 0.24782921 | M22: 0.24463409 | N22: 0.24145885 | O22: 0.19366936 | P22: 0.14032364 | Q22: 0.082603867 | R22: 0.080647999 | S22: 0 | T22: 0 | U22: 0
A23: Golf Centre | B23: 0.1 | C23: 0.1 | D23: 0.10695652 | E23: 0.10695652 | F23: 0.10695652 | G23: 0.10563471 | H23: 0.1043197 | I23: 0.1030117 | J23: 0.1017109 | K23: 0.1004175 | L23: 0.099131682 | M23: 0.097853637 | N23: 0.09658354 | O23: 0.1009073 | P23: 0.10483181 | Q23: 0.10899913 | R23: 0.10641828 | S23: 0.11276228 | T23: 0.10983869 | U23: 0.10698176
B24: =SUM(B20:B23) -> 1 | C24: =SUM(C20:C23) -> 1 | D24: =SUM(D20:D23) -> 1 | E24: =SUM(E20:E23) -> 1 | F24: =SUM(F20:F23) -> 1 | G24: =SUM(G20:G23) -> 1 | H24: =SUM(H20:H23) -> 1 | I24: =SUM(I20:I23) -> 1 | ... U24: =SUM(U20:U23) -> 1
A25: Base Case
A26: Interim Facility Revenue | B26: =IF($B$3="Base Case",B$15*B20,IF($B$3="Worst Case",B$16*B20,IF($B$3="Best Case",B$17*B20,""))) -> 5596500 | C26: =IF($B$3="Base Case",C$15*C20,IF($B$3="Worst Case",C$16*C20,IF($B$3="Best Case",C$17*C20,""))) -> 5596500 | D26: =IF($B$3="Base Case",D$15*D20,IF($B$3="Worst Case",D$16*D20,IF($B$3="Best Case",D$17*D20,""))) -> 0 | E26: =IF($B$3="Base Case",E$15*E20,IF($B$3="Worst Case",E$16*E20,IF($B$3="Best Case",E$17*E20,""))) -> 0 | F26: =IF($B$3="Base Case",F$15*F20,IF($B$3="Worst Case",F$16*F20,IF($B$3="Best Case",F$17*F20,""))) -> 0 | G26: =IF($B$3="Base Case",G$15*G20,IF($B$3="Worst Case",G$16*G20,IF($B$3="Best Case",G$17*G20,""))) -> 0 | H26: =IF($B$3="Base Case",H$15*H20,IF($B$3="Worst Case",H$16*H20,IF($B$3="Best Case",H$17*H20,""))) -> 0 | I26: =IF($B$3="Base Case",I$15*I20,IF($B$3="Worst Case",I$16*I20,IF($B$3="Best Case",I$17*I20,""))) -> 0 | ... U26: =IF($B$3="Base Case",U$15*U20,IF($B$3="Worst Case",U$16*U20,IF($B$3="Best Case",U$17*U20,""))) -> 0
A27: New flagship Revenue | B27: =IF($B$3="Base Case",B$15*B21,IF($B$3="Worst Case",B$16*B21,IF($B$3="Best Case",B$17*B21,""))) -> 0 | C27: =IF($B$3="Base Case",C$15*C21,IF($B$3="Worst Case",C$16*C21,IF($B$3="Best Case",C$17*C21,""))) -> 0 | D27: =IF(B51>0,0,IF($B$3="Base Case",D$15*D21,IF($B$3="Worst Case",D$16*D21,IF($B$3="Best Case",D$17*D21,"")))) -> 5036500 | E27: =IF(B51>1,0,IF($B$3="Base Case",E$15*E21,IF($B$3="Worst Case",E$16*E21,IF($B$3="Best Case",E$17*E21,"")))) -> 5036500 | F27: =IF($B$51>COLUMN(B1),0,IF($B$3="Base Case",F$15*F21,IF($B$3="Worst Case",F$16*F21,IF($B$3="Best Case",F$17*F21,"")))) -> 5036500 | G27: =IF($B$51>COLUMN(C1),0,IF($B$3="Base Case",G$15*G21,IF($B$3="Worst Case",G$16*G21,IF($B$3="Best Case",G$17*G21,"")))) -> 5137230 | H27: =IF($B$51>COLUMN(D1),0,IF($B$3="Base Case",H$15*H21,IF($B$3="Worst Case",H$16*H21,IF($B$3="Best Case",H$17*H21,"")))) -> 5239974.6 | I27: =IF($B$51>COLUMN(E1),0,IF($B$3="Base Case",I$15*I21,IF($B$3="Worst Case",I$16*I21,IF($B$3="Best Case",I$17*I21,"")))) -> 5344774.1 | J27: =IF($B$51>COLUMN(F1),0,IF($B$3="Base Case",J$15*J21,IF($B$3="Worst Case",J$16*J21,IF($B$3="Best Case",J$17*J21,"")))) -> 5451669.6 | K27: =IF($B$51>COLUMN(G1),0,IF($B$3="Base Case",K$15*K21,IF($B$3="Worst Case",K$16*K21,IF($B$3="Best Case",K$17*K21,"")))) -> 5560703 | L27: =IF($B$51>COLUMN(H1),0,IF($B$3="Base Case",L$15*L21,IF($B$3="Worst Case",L$16*L21,IF($B$3="Best Case",L$17*L21,"")))) -> 5671917 | M27: =IF($B$51>COLUMN(I1),0,IF($B$3="Base Case",M$15*M21,IF($B$3="Worst Case",M$16*M21,IF($B$3="Best Case",M$17*M21,"")))) -> 5785355.4 | ... U27: =IF($B$51>COLUMN(Q1),0,IF($B$3="Base Case",U$15*U21,IF($B$3="Worst Case",U$16*U21,IF($B$3="Best Case",U$17*U21,"")))) -> 7187100.7
A28: Health & Fitness (Small) | B28: =IF($B$3="Base Case",B$15*B22,IF($B$3="Worst Case",B$16*B22,IF($B$3="Best Case",B$17*B22,""))) -> 2152500 | C28: =IF($B$3="Base Case",C$15*C22,IF($B$3="Worst Case",C$16*C22,IF($B$3="Best Case",C$17*C22,""))) -> 2152500 | D28: =IF($B$3="Base Case",D$15*D22,IF($B$3="Worst Case",D$16*D22,IF($B$3="Best Case",D$17*D22,""))) -> 2152500 | E28: =IF($B$3="Base Case",E$15*E22,IF($B$3="Worst Case",E$16*E22,IF($B$3="Best Case",E$17*E22,""))) -> 2152500 | F28: =IF($B$3="Base Case",F$15*F22,IF($B$3="Worst Case",F$16*F22,IF($B$3="Best Case",F$17*F22,""))) -> 2152500 | G28: =IF($B$3="Base Case",G$15*G22,IF($B$3="Worst Case",G$16*G22,IF($B$3="Best Case",G$17*G22,""))) -> 2152500 | H28: =IF($B$3="Base Case",H$15*H22,IF($B$3="Worst Case",H$16*H22,IF($B$3="Best Case",H$17*H22,""))) -> 2152500 | I28: =IF($B$3="Base Case",I$15*I22,IF($B$3="Worst Case",I$16*I22,IF($B$3="Best Case",I$17*I22,""))) -> 2152500 | ... U28: =IF($B$3="Base Case",U$15*U22,IF($B$3="Worst Case",U$16*U22,IF($B$3="Best Case",U$17*U22,""))) -> 0
A29: Golf Centre | B29: =IF($B$3="Base Case",B$15*B23,IF($B$3="Worst Case",B$16*B23,IF($B$3="Best Case",B$17*B23,""))) -> 861000 | C29: =IF($B$3="Base Case",C$15*C23,IF($B$3="Worst Case",C$16*C23,IF($B$3="Best Case",C$17*C23,""))) -> 861000 | D29: =IF($B$3="Base Case",D$15*D23,IF($B$3="Worst Case",D$16*D23,IF($B$3="Best Case",D$17*D23,""))) -> 861000 | E29: =IF($B$3="Base Case",E$15*E23,IF($B$3="Worst Case",E$16*E23,IF($B$3="Best Case",E$17*E23,""))) -> 861000 | F29: =IF($B$3="Base Case",F$15*F23,IF($B$3="Worst Case",F$16*F23,IF($B$3="Best Case",F$17*F23,""))) -> 861000 | G29: =IF($B$3="Base Case",G$15*G23,IF($B$3="Worst Case",G$16*G23,IF($B$3="Best Case",G$17*G23,""))) -> 861000 | H29: =IF($B$3="Base Case",H$15*H23,IF($B$3="Worst Case",H$16*H23,IF($B$3="Best Case",H$17*H23,""))) -> 861000 | I29: =IF($B$3="Base Case",I$15*I23,IF($B$3="Worst Case",I$16*I23,IF($B$3="Best Case",I$17*I23,""))) -> 861000 | ... U29: =IF($B$3="Base Case",U$15*U23,IF($B$3="Worst Case",U$16*U23,IF($B$3="Best Case",U$17*U23,""))) -> 861000
B32: =IF($B$3="Base Case",B$15*B20,IF($B$3="Worst Case",B$16*B20,IF($B$3="Best Case",B$17*B20,""))) -> 5596500 | C32: =IF($B$3="Base Case",C$15*C20,IF($B$3="Worst Case",C$16*C20,IF($B$3="Best Case",C$17*C20,""))) -> 5596500 | D32: =IF($B$3="Base Case",D$15*D20,IF($B$3="Worst Case",D$16*D20,IF($B$3="Best Case",D$17*D20,""))) -> 0 | E32: =IF($B$3="Base Case",E$15*E20,IF($B$3="Worst Case",E$16*E20,IF($B$3="Best Case",E$17*E20,""))) -> 0 | F32: =IF($B$3="Base Case",F$15*F20,IF($B$3="Worst Case",F$16*F20,IF($B$3="Best Case",F$17*F20,""))) -> 0 | G32: =IF($B$3="Base Case",G$15*G20,IF($B$3="Worst Case",G$16*G20,IF($B$3="Best Case",G$17*G20,""))) -> 0 | H32: =IF($B$3="Base Case",H$15*H20,IF($B$3="Worst Case",H$16*H20,IF($B$3="Best Case",H$17*H20,""))) -> 0 | I32: =IF($B$3="Base Case",I$15*I20,IF($B$3="Worst Case",I$16*I20,IF($B$3="Best Case",I$17*I20,""))) -> 0 | ... U32: =IF($B$3="Base Case",U$15*U20,IF($B$3="Worst Case",U$16*U20,IF($B$3="Best Case",U$17*U20,""))) -> 0
B33: =IF($B$3="Base Case",B$15*B21,IF($B$3="Worst Case",B$16*B21,IF($B$3="Best Case",B$17*B21,""))) -> 0 | C33: =IF($B$3="Base Case",C$15*C21,IF($B$3="Worst Case",C$16*C21,IF($B$3="Best Case",C$17*C21,""))) -> 0 | D33: =IF($B$3="Base Case",D$15*D21,IF($B$3="Worst Case",D$16*D21,IF($B$3="Best Case",D$17*D21,""))) -> 5036500 | E33: =IF($B$3="Base Case",E$15*E21,IF($B$3="Worst Case",E$16*E21,IF($B$3="Best Case",E$17*E21,""))) -> 5036500 | F33: =IF($B$3="Base Case",F$15*F21,IF($B$3="Worst Case",F$16*F21,IF($B$3="Best Case",F$17*F21,""))) -> 5036500 | G33: =IF($B$3="Base Case",G$15*G21,IF($B$3="Worst Case",G$16*G21,IF($B$3="Best Case",G$17*G21,""))) -> 5137230 | H33: =IF($B$3="Base Case",H$15*H21,IF($B$3="Worst Case",H$16*H21,IF($B$3="Best Case",H$17*H21,""))) -> 5239974.6 | I33: =IF($B$3="Base Case",I$15*I21,IF($B$3="Worst Case",I$16*I21,IF($B$3="Best Case",I$17*I21,""))) -> 5344774.1 | ... U33: =IF($B$3="Base Case",U$15*U21,IF($B$3="Worst Case",U$16*U21,IF($B$3="Best Case",U$17*U21,""))) -> 7187100.7
B34: =IF($B$3="Base Case",B$15*B22,IF($B$3="Worst Case",B$16*B22,IF($B$3="Best Case",B$17*B22,""))) -> 2152500 | C34: =IF($B$3="Base Case",C$15*C22,IF($B$3="Worst Case",C$16*C22,IF($B$3="Best Case",C$17*C22,""))) -> 2152500 | D34: =IF($B$3="Base Case",D$15*D22,IF($B$3="Worst Case",D$16*D22,IF($B$3="Best Case",D$17*D22,""))) -> 2152500 | E34: =IF($B$3="Base Case",E$15*E22,IF($B$3="Worst Case",E$16*E22,IF($B$3="Best Case",E$17*E22,""))) -> 2152500 | F34: =IF($B$3="Base Case",F$15*F22,IF($B$3="Worst Case",F$16*F22,IF($B$3="Best Case",F$17*F22,""))) -> 2152500 | G34: =IF($B$3="Base Case",G$15*G22,IF($B$3="Worst Case",G$16*G22,IF($B$3="Best Case",G$17*G22,""))) -> 2152500 | H34: =IF($B$3="Base Case",H$15*H22,IF($B$3="Worst Case",H$16*H22,IF($B$3="Best Case",H$17*H22,""))) -> 2152500 | I34: =IF($B$3="Base Case",I$15*I22,IF($B$3="Worst Case",I$16*I22,IF($B$3="Best Case",I$17*I22,""))) -> 2152500 | ... U34: =IF($B$3="Base Case",U$15*U22,IF($B$3="Worst Case",U$16*U22,IF($B$3="Best Case",U$17*U22,""))) -> 0
B35: =IF($B$3="Base Case",B$15*B23,IF($B$3="Worst Case",B$16*B23,IF($B$3="Best Case",B$17*B23,""))) -> 861000 | C35: =IF($B$3="Base Case",C$15*C23,IF($B$3="Worst Case",C$16*C23,IF($B$3="Best Case",C$17*C23,""))) -> 861000 | D35: =IF($B$3="Base Case",D$15*D23,IF($B$3="Worst Case",D$16*D23,IF($B$3="Best Case",D$17*D23,""))) -> 861000 | E35: =IF($B$3="Base Case",E$15*E23,IF($B$3="Worst Case",E$16*E23,IF($B$3="Best Case",E$17*E23,""))) -> 861000 | F35: =IF($B$3="Base Case",F$15*F23,IF($B$3="Worst Case",F$16*F23,IF($B$3="Best Case",F$17*F23,""))) -> 861000 | G35: =IF($B$3="Base Case",G$15*G23,IF($B$3="Worst Case",G$16*G23,IF($B$3="Best Case",G$17*G23,""))) -> 861000 | H35: =IF($B$3="Base Case",H$15*H23,IF($B$3="Worst Case",H$16*H23,IF($B$3="Best Case",H$17*H23,""))) -> 861000 | I35: =IF($B$3="Base Case",I$15*I23,IF($B$3="Worst Case",I$16*I23,IF($B$3="Best Case",I$17*I23,""))) -> 861000 | ... U35: =IF($B$3="Base Case",U$15*U23,IF($B$3="Worst Case",U$16*U23,IF($B$3="Best Case",U$17*U23,""))) -> 861000
A37: Operating Expenditure | B37: 5970000
A38: Staff Cost | B38: 0.45
A39: Utilites | B39: 0.25
A40: Repairs & Maintenance | B40: 0.2
A41: Other opex | B41: 0.1
A43: Growth Rate | B43: 0.02
A46: INITIAL INVESTMENT | B46: =SUM('Opreating Cashflow'!B34:D34) -> -9610
A47: NPV | B47: =NPV(B60,'Opreating Cashflow'!B27:U27) -> 14440.314
A48: VALUE CREATION | B48: =+B46+B47 -> 4830.3135
A51: Delay in Centre opening | B51: =DASHBOARD!E15 -> 0
A52: 0
...

Sheet Opreating Cashflow (2)
A1: Descriptions | B1: =+Data!B8 -> Year1 | C1: =+Data!C8 -> Year2 | D1: =+Data!D8 -> Year3 | E1: =+Data!E8 -> Year4 | F1: =+Data!F8 -> Year5 | G1: =+Data!G8 -> Year6 | H1: =+Data!H8 -> Year7 | I1: =+Data!I8 -> Year8 | ... U1: =+Data!U8 -> Year20
A3: REVENUE
A4: Interim Facility Revenue | B4: =IF(Data!$B$3="Base Case",Data!$B$4*VLOOKUP('Opreating Cashflow (2)'!$A4,Data!$A$9:$U$12,COLUMN(B1),0)/1000,IF(Data!$B$3="Worst Case",Data!$B$5*VLOOKUP('Opreating Cashflow (2)'!$A4,Data!$A$9:$U$12,COLUMN(B1),0)/1000,IF(Data!$B$3="Best Case",Data!$B$6*VLOOKUP('Opreating Cashflow (2)'!$A4,Data!$A$9:$U$12,COLUMN(B1),0)/1000,""))) -> 5596.5 | C4: =IF(Data!$B$3="Base Case",Data!$B$4*VLOOKUP('Opreating Cashflow (2)'!$A4,Data!$A$9:$U$12,COLUMN(C1),0)/1000,IF(Data!$B$3="Worst Case",Data!$B$5*VLOOKUP('Opreating Cashflow (2)'!$A4,Data!$A$9:$U$12,COLUMN(C1),0)/1000,IF(Data!$B$3="Best Case",Data!$B$6*VLOOKUP('Opreating Cashflow (2)'!$A4,Data!$A$9:$U$12,COLUMN(C1),0)/1000,""))) -> 5596.5 | D4: =IF(Data!$B$3="Base Case",Data!$B$4*VLOOKUP('Opreating Cashflow (2)'!$A4,Data!$A$9:$U$12,COLUMN(D1),0)/1000,IF(Data!$B$3="Worst Case",Data!$B$5*VLOOKUP('Opreating Cashflow (2)'!$A4,Data!$A$9:$U$12,COLUMN(D1),0)/1000,IF(Data!$B$3="Best Case",Data!$B$6*VLOOKUP('Opreating Cashflow (2)'!$A4,Data!$A$9:$U$12,COLUMN(D1),0)/1000,""))) -> 0 | E4: =IF(Data!$B$3="Base Case",Data!$B$4*VLOOKUP('Opreating Cashflow (2)'!$A4,Data!$A$9:$U$12,COLUMN(E1),0)/1000,IF(Data!$B$3="Worst Case",Data!$B$5*VLOOKUP('Opreating Cashflow (2)'!$A4,Data!$A$9:$U$12,COLUMN(E1),0)/1000,IF(Data!$B$3="Best Case",Data!$B$6*VLOOKUP('Opreating Cashflow (2)'!$A4,Data!$A$9:$U$12,COLUMN(E1),0)/1000,""))) -> 0 | F4: =IF(Data!$B$3="Base Case",Data!$B$4*VLOOKUP('Opreating Cashflow (2)'!$A4,Data!$A$9:$U$12,COLUMN(F1),0)/1000,IF(Data!$B$3="Worst Case",Data!$B$5*VLOOKUP('Opreating Cashflow (2)'!$A4,Data!$A$9:$U$12,COLUMN(F1),0)/1000,IF(Data!$B$3="Best Case",Data!$B$6*VLOOKUP('Opreating Cashflow (2)'!$A4,Data!$A$9:$U$12,COLUMN(F1),0)/1000,""))) -> 0 | G4: =IF(Data!$B$3="Base Case",Data!$B$4*VLOOKUP('Opreating Cashflow (2)'!$A4,Data!$A$9:$U$12,COLUMN(G1),0)/1000,IF(Data!$B$3="Worst Case",Data!$B$5*VLOOKUP('Opreating Cashflow (2)'!$A4,Data!$A$9:$U$12,COLUMN(G1),0)/1000,IF(Data!$B$3="Best Case",Data!$B$6*VLOOKUP('Opreating Cashflow (2)'!$A4,Data!$A$9:$U$12,COLUMN(G1),0)/1000,""))) -> 0 | H4: =IF(Data!$B$3="Base Case",Data!$B$4*VLOOKUP('Opreating Cashflow (2)'!$A4,Data!$A$9:$U$12,COLUMN(H1),0)/1000,IF(Data!$B$3="Worst Case",Data!$B$5*VLOOKUP('Opreating Cashflow (2)'!$A4,Data!$A$9:$U$12,COLUMN(H1),0)/1000,IF(Data!$B$3="Best Case",Data!$B$6*VLOOKUP('Opreating Cashflow (2)'!$A4,Data!$A$9:$U$12,COLUMN(H1),0)/1000,""))) -> 0 | I4: =IF(Data!$B$3="Base Case",Data!$B$4*VLOOKUP('Opreating Cashflow (2)'!$A4,Data!$A$9:$U$12,COLUMN(I1),0)/1000,IF(Data!$B$3="Worst Case",Data!$B$5*VLOOKUP('Opreating Cashflow (2)'!$A4,Data!$A$9:$U$12,COLUMN(I1),0)/1000,IF(Data!$B$3="Best Case",Data!$B$6*VLOOKUP('Opreating Cashflow (2)'!$A4,Data!$A$9:$U$12,COLUMN(I1),0)/1000,""))) -> 0 | ... U4: =IF(Data!$B$3="Base Case",Data!$B$4*VLOOKUP('Opreating Cashflow (2)'!$A4,Data!$A$9:$U$12,COLUMN(U1),0)/1000,IF(Data!$B$3="Worst Case",Data!$B$5*VLOOKUP('Opreating Cashflow (2)'!$A4,Data!$A$9:$U$12,COLUMN(U1),0)/1000,IF(Data!$B$3="Best Case",Data!$B$6*VLOOKUP('Opreating Cashflow (2)'!$A4,Data!$A$9:$U$12,COLUMN(U1),0)/1000,""))) -> 0
A5: New flagship Revenue | B5: =IF(Data!$B$3="Base Case",Data!$B$4*VLOOKUP('Opreating Cashflow (2)'!$A5,Data!$A$9:$U$12,COLUMN(B4),0)/1000,IF(Data!$B$3="Worst Case",Data!$B$5*VLOOKUP('Opreating Cashflow (2)'!$A5,Data!$A$9:$U$12,COLUMN(B4),0)/1000,IF(Data!$B$3="Best Case",Data!$B$6*VLOOKUP('Opreating Cashflow (2)'!$A5,Data!$A$9:$U$12,COLUMN(B4),0)/1000,""))) -> 0 | C5: =IF(Data!$B$3="Base Case",Data!$B$4*VLOOKUP('Opreating Cashflow (2)'!$A5,Data!$A$9:$U$12,COLUMN(C4),0)/1000,IF(Data!$B$3="Worst Case",Data!$B$5*VLOOKUP('Opreating Cashflow (2)'!$A5,Data!$A$9:$U$12,COLUMN(C4),0)/1000,IF(Data!$B$3="Best Case",Data!$B$6*VLOOKUP('Opreating Cashflow (2)'!$A5,Data!$A$9:$U$12,COLUMN(C4),0)/1000,""))) -> 0 | D5: =IF(Data!$B$3="Base Case",Data!$B$4*VLOOKUP('Opreating Cashflow (2)'!$A5,Data!$A$9:$U$12,COLUMN(D4),0)/1000,IF(Data!$B$3="Worst Case",Data!$B$5*VLOOKUP('Opreating Cashflow (2)'!$A5,Data!$A$9:$U$12,COLUMN(D4),0)/1000,IF(Data!$B$3="Best Case",Data!$B$6*VLOOKUP('Opreating Cashflow (2)'!$A5,Data!$A$9:$U$12,COLUMN(D4),0)/1000,""))) -> 5596.5 | E5: =IF(Data!$B$3="Base Case",Data!$B$4*VLOOKUP('Opreating Cashflow (2)'!$A5,Data!$A$9:$U$12,COLUMN(E4),0)/1000,IF(Data!$B$3="Worst Case",Data!$B$5*VLOOKUP('Opreating Cashflow (2)'!$A5,Data!$A$9:$U$12,COLUMN(E4),0)/1000,IF(Data!$B$3="Best Case",Data!$B$6*VLOOKUP('Opreating Cashflow (2)'!$A5,Data!$A$9:$U$12,COLUMN(E4),0)/1000,""))) -> 5596.5 | F5: =IF(Data!$B$3="Base Case",Data!$B$4*VLOOKUP('Opreating Cashflow (2)'!$A5,Data!$A$9:$U$12,COLUMN(F4),0)/1000,IF(Data!$B$3="Worst Case",Data!$B$5*VLOOKUP('Opreating Cashflow (2)'!$A5,Data!$A$9:$U$12,COLUMN(F4),0)/1000,IF(Data!$B$3="Best Case",Data!$B$6*VLOOKUP('Opreating Cashflow (2)'!$A5,Data!$A$9:$U$12,COLUMN(F4),0)/1000,""))) -> 5596.5 | G5: =IF(Data!$B$3="Base Case",Data!$B$4*VLOOKUP('Opreating Cashflow (2)'!$A5,Data!$A$9:$U$12,COLUMN(G4),0)/1000,IF(Data!$B$3="Worst Case",Data!$B$5*VLOOKUP('Opreating Cashflow (2)'!$A5,Data!$A$9:$U$12,COLUMN(G4),0)/1000,IF(Data!$B$3="Best Case",Data!$B$6*VLOOKUP('Opreating Cashflow (2)'!$A5,Data!$A$9:$U$12,COLUMN(G4),0)/1000,""))) -> 6027 | H5: =IF(Data!$B$3="Base Case",Data!$B$4*VLOOKUP('Opreating Cashflow (2)'!$A5,Data!$A$9:$U$12,COLUMN(H4),0)/1000,IF(Data!$B$3="Worst Case",Data!$B$5*VLOOKUP('Opreating Cashflow (2)'!$A5,Data!$A$9:$U$12,COLUMN(H4),0)/1000,IF(Data!$B$3="Best Case",Data!$B$6*VLOOKUP('Opreating Cashflow (2)'!$A5,Data!$A$9:$U$12,COLUMN(H4),0)/1000,""))) -> 6027 | I5: =IF(Data!$B$3="Base Case",Data!$B$4*VLOOKUP('Opreating Cashflow (2)'!$A5,Data!$A$9:$U$12,COLUMN(I4),0)/1000,IF(Data!$B$3="Worst Case",Data!$B$5*VLOOKUP('Opreating Cashflow (2)'!$A5,Data!$A$9:$U$12,COLUMN(I4),0)/1000,IF(Data!$B$3="Best Case",Data!$B$6*VLOOKUP('Opreating Cashflow (2)'!$A5,Data!$A$9:$U$12,COLUMN(I4),0)/1000,""))) -> 6027 | ... U5: =IF(Data!$B$3="Base Case",Data!$B$4*VLOOKUP('Opreating Cashflow (2)'!$A5,Data!$A$9:$U$12,COLUMN(U4),0)/1000,IF(Data!$B$3="Worst Case",Data!$B$5*VLOOKUP('Opreating Cashflow (2)'!$A5,Data!$A$9:$U$12,COLUMN(U4),0)/1000,IF(Data!$B$3="Best Case",Data!$B$6*VLOOKUP('Opreating Cashflow (2)'!$A5,Data!$A$9:$U$12,COLUMN(U4),0)/1000,""))) -> 7318.5
A6: Health & Fitness (Small) | B6: =IF(Data!$B$3="Base Case",Data!$B$4*VLOOKUP('Opreating Cashflow (2)'!$A6,Data!$A$9:$U$12,COLUMN(B5),0)/1000,IF(Data!$B$3="Worst Case",Data!$B$5*VLOOKUP('Opreating Cashflow (2)'!$A6,Data!$A$9:$U$12,COLUMN(B5),0)/1000,IF(Data!$B$3="Best Case",Data!$B$6*VLOOKUP('Opreating Cashflow (2)'!$A6,Data!$A$9:$U$12,COLUMN(B5),0)/1000,""))) -> 1722 | C6: =IF(Data!$B$3="Base Case",Data!$B$4*VLOOKUP('Opreating Cashflow (2)'!$A6,Data!$A$9:$U$12,COLUMN(C5),0)/1000,IF(Data!$B$3="Worst Case",Data!$B$5*VLOOKUP('Opreating Cashflow (2)'!$A6,Data!$A$9:$U$12,COLUMN(C5),0)/1000,IF(Data!$B$3="Best Case",Data!$B$6*VLOOKUP('Opreating Cashflow (2)'!$A6,Data!$A$9:$U$12,COLUMN(C5),0)/1000,""))) -> 1722 | D6: =IF(Data!$B$3="Base Case",Data!$B$4*VLOOKUP('Opreating Cashflow (2)'!$A6,Data!$A$9:$U$12,COLUMN(D5),0)/1000,IF(Data!$B$3="Worst Case",Data!$B$5*VLOOKUP('Opreating Cashflow (2)'!$A6,Data!$A$9:$U$12,COLUMN(D5),0)/1000,IF(Data!$B$3="Best Case",Data!$B$6*VLOOKUP('Opreating Cashflow (2)'!$A6,Data!$A$9:$U$12,COLUMN(D5),0)/1000,""))) -> 1722 | E6: =IF(Data!$B$3="Base Case",Data!$B$4*VLOOKUP('Opreating Cashflow (2)'!$A6,Data!$A$9:$U$12,COLUMN(E5),0)/1000,IF(Data!$B$3="Worst Case",Data!$B$5*VLOOKUP('Opreating Cashflow (2)'!$A6,Data!$A$9:$U$12,COLUMN(E5),0)/1000,IF(Data!$B$3="Best Case",Data!$B$6*VLOOKUP('Opreating Cashflow (2)'!$A6,Data!$A$9:$U$12,COLUMN(E5),0)/1000,""))) -> 1722 | F6: =IF(Data!$B$3="Base Case",Data!$B$4*VLOOKUP('Opreating Cashflow (2)'!$A6,Data!$A$9:$U$12,COLUMN(F5),0)/1000,IF(Data!$B$3="Worst Case",Data!$B$5*VLOOKUP('Opreating Cashflow (2)'!$A6,Data!$A$9:$U$12,COLUMN(F5),0)/1000,IF(Data!$B$3="Best Case",Data!$B$6*VLOOKUP('Opreating Cashflow (2)'!$A6,Data!$A$9:$U$12,COLUMN(F5),0)/1000,""))) -> 1722 | G6: =IF(Data!$B$3="Base Case",Data!$B$4*VLOOKUP('Opreating Cashflow (2)'!$A6,Data!$A$9:$U$12,COLUMN(G5),0)/1000,IF(Data!$B$3="Worst Case",Data!$B$5*VLOOKUP('Opreating Cashflow (2)'!$A6,Data!$A$9:$U$12,COLUMN(G5),0)/1000,IF(Data!$B$3="Best Case",Data!$B$6*VLOOKUP('Opreating Cashflow (2)'!$A6,Data!$A$9:$U$12,COLUMN(G5),0)/1000,""))) -> 1291.5 | H6: =IF(Data!$B$3="Base Case",Data!$B$4*VLOOKUP('Opreating Cashflow (2)'!$A6,Data!$A$9:$U$12,COLUMN(H5),0)/1000,IF(Data!$B$3="Worst Case",Data!$B$5*VLOOKUP('Opreating Cashflow (2)'!$A6,Data!$A$9:$U$12,COLUMN(H5),0)/1000,IF(Data!$B$3="Best Case",Data!$B$6*VLOOKUP('Opreating Cashflow (2)'!$A6,Data!$A$9:$U$12,COLUMN(H5),0)/1000,""))) -> 1291.5 | I6: =IF(Data!$B$3="Base Case",Data!$B$4*VLOOKUP('Opreating Cashflow (2)'!$A6,Data!$A$9:$U$12,COLUMN(I5),0)/1000,IF(Data!$B$3="Worst Case",Data!$B$5*VLOOKUP('Opreating Cashflow (2)'!$A6,Data!$A$9:$U$12,COLUMN(I5),0)/1000,IF(Data!$B$3="Best Case",Data!$B$6*VLOOKUP('Opreating Cashflow (2)'!$A6,Data!$A$9:$U$12,COLUMN(I5),0)/1000,""))) -> 1291.5 | ... U6: =IF(Data!$B$3="Base Case",Data!$B$4*VLOOKUP('Opreating Cashflow (2)'!$A6,Data!$A$9:$U$12,COLUMN(U5),0)/1000,IF(Data!$B$3="Worst Case",Data!$B$5*VLOOKUP('Opreating Cashflow (2)'!$A6,Data!$A$9:$U$12,COLUMN(U5),0)/1000,IF(Data!$B$3="Best Case",Data!$B$6*VLOOKUP('Opreating Cashflow (2)'!$A6,Data!$A$9:$U$12,COLUMN(U5),0)/1000,""))) -> 0
A7: Golf Centre | B7: =IF(Data!$B$3="Base Case",Data!$B$4*VLOOKUP('Opreating Cashflow (2)'!$A7,Data!$A$9:$U$12,COLUMN(B6),0)/1000,IF(Data!$B$3="Worst Case",Data!$B$5*VLOOKUP('Opreating Cashflow (2)'!$A7,Data!$A$9:$U$12,COLUMN(B6),0)/1000,IF(Data!$B$3="Best Case",Data!$B$6*VLOOKUP('Opreating Cashflow (2)'!$A7,Data!$A$9:$U$12,COLUMN(B6),0)/1000,""))) -> 1291.5 | C7: =IF(Data!$B$3="Base Case",Data!$B$4*VLOOKUP('Opreating Cashflow (2)'!$A7,Data!$A$9:$U$12,COLUMN(C6),0)/1000,IF(Data!$B$3="Worst Case",Data!$B$5*VLOOKUP('Opreating Cashflow (2)'!$A7,Data!$A$9:$U$12,COLUMN(C6),0)/1000,IF(Data!$B$3="Best Case",Data!$B$6*VLOOKUP('Opreating Cashflow (2)'!$A7,Data!$A$9:$U$12,COLUMN(C6),0)/1000,""))) -> 1291.5 | D7: =IF(Data!$B$3="Base Case",Data!$B$4*VLOOKUP('Opreating Cashflow (2)'!$A7,Data!$A$9:$U$12,COLUMN(D6),0)/1000,IF(Data!$B$3="Worst Case",Data!$B$5*VLOOKUP('Opreating Cashflow (2)'!$A7,Data!$A$9:$U$12,COLUMN(D6),0)/1000,IF(Data!$B$3="Best Case",Data!$B$6*VLOOKUP('Opreating Cashflow (2)'!$A7,Data!$A$9:$U$12,COLUMN(D6),0)/1000,""))) -> 1291.5 | E7: =IF(Data!$B$3="Base Case",Data!$B$4*VLOOKUP('Opreating Cashflow (2)'!$A7,Data!$A$9:$U$12,COLUMN(E6),0)/1000,IF(Data!$B$3="Worst Case",Data!$B$5*VLOOKUP('Opreating Cashflow (2)'!$A7,Data!$A$9:$U$12,COLUMN(E6),0)/1000,IF(Data!$B$3="Best Case",Data!$B$6*VLOOKUP('Opreating Cashflow (2)'!$A7,Data!$A$9:$U$12,COLUMN(E6),0)/1000,""))) -> 1291.5 | F7: =IF(Data!$B$3="Base Case",Data!$B$4*VLOOKUP('Opreating Cashflow (2)'!$A7,Data!$A$9:$U$12,COLUMN(F6),0)/1000,IF(Data!$B$3="Worst Case",Data!$B$5*VLOOKUP('Opreating Cashflow (2)'!$A7,Data!$A$9:$U$12,COLUMN(F6),0)/1000,IF(Data!$B$3="Best Case",Data!$B$6*VLOOKUP('Opreating Cashflow (2)'!$A7,Data!$A$9:$U$12,COLUMN(F6),0)/1000,""))) -> 1291.5 | G7: =IF(Data!$B$3="Base Case",Data!$B$4*VLOOKUP('Opreating Cashflow (2)'!$A7,Data!$A$9:$U$12,COLUMN(G6),0)/1000,IF(Data!$B$3="Worst Case",Data!$B$5*VLOOKUP('Opreating Cashflow (2)'!$A7,Data!$A$9:$U$12,COLUMN(G6),0)/1000,IF(Data!$B$3="Best Case",Data!$B$6*VLOOKUP('Opreating Cashflow (2)'!$A7,Data!$A$9:$U$12,COLUMN(G6),0)/1000,""))) -> 1291.5 | H7: =IF(Data!$B$3="Base Case",Data!$B$4*VLOOKUP('Opreating Cashflow (2)'!$A7,Data!$A$9:$U$12,COLUMN(H6),0)/1000,IF(Data!$B$3="Worst Case",Data!$B$5*VLOOKUP('Opreating Cashflow (2)'!$A7,Data!$A$9:$U$12,COLUMN(H6),0)/1000,IF(Data!$B$3="Best Case",Data!$B$6*VLOOKUP('Opreating Cashflow (2)'!$A7,Data!$A$9:$U$12,COLUMN(H6),0)/1000,""))) -> 1291.5 | I7: =IF(Data!$B$3="Base Case",Data!$B$4*VLOOKUP('Opreating Cashflow (2)'!$A7,Data!$A$9:$U$12,COLUMN(I6),0)/1000,IF(Data!$B$3="Worst Case",Data!$B$5*VLOOKUP('Opreating Cashflow (2)'!$A7,Data!$A$9:$U$12,COLUMN(I6),0)/1000,IF(Data!$B$3="Best Case",Data!$B$6*VLOOKUP('Opreating Cashflow (2)'!$A7,Data!$A$9:$U$12,COLUMN(I6),0)/1000,""))) -> 1291.5 | ... U7: =IF(Data!$B$3="Base Case",Data!$B$4*VLOOKUP('Opreating Cashflow (2)'!$A7,Data!$A$9:$U$12,COLUMN(U6),0)/1000,IF(Data!$B$3="Worst Case",Data!$B$5*VLOOKUP('Opreating Cashflow (2)'!$A7,Data!$A$9:$U$12,COLUMN(U6),0)/1000,IF(Data!$B$3="Best Case",Data!$B$6*VLOOKUP('Opreating Cashflow (2)'!$A7,Data!$A$9:$U$12,COLUMN(U6),0)/1000,""))) -> 1291.5
A8: TOTAL REVENUE | B8: =SUM(B4:B7) -> 8610 | C8: =SUM(C4:C7) -> 8610 | D8: =SUM(D4:D7) -> 8610 | E8: =SUM(E4:E7) -> 8610 | F8: =SUM(F4:F7) -> 8610 | G8: =SUM(G4:G7) -> 8610 | H8: =SUM(H4:H7) -> 8610 | I8: =SUM(I4:I7) -> 8610 | ... U8: =SUM(U4:U7) -> 8610
A11: OPERATING EXPENDITURE
A12: Staff Cost | B12: =-Data!$B$37*VLOOKUP('Opreating Cashflow (2)'!$A12,Data!$A$38:$B$41,2,0)/1000 -> -2686.5 | C12: =(+B12*(2.5%/4))+B12 -> -2703.2906 | D12: =(+C12*(2.5%/4))+C12 -> -2720.1862 | E12: =(+D12*(2.5%/4))+D12 -> -2737.1874 | F12: =(+E12*(2.5%/4))+E12 -> -2754.2948 | G12: =(+F12*(2.5%/4))+F12 -> -2771.5091 | H12: =(+G12*(2.5%/4))+G12 -> -2788.8311 | I12: =(+H12*(2.5%/4))+H12 -> -2806.2612 | J12: =(+I12*(2.5%/4))+I12 -> -2823.8004 | ... U12: =(+T12*(2.5%/4))+T12 -> -3024.1186
A13: Utilites | B13: =-Data!$B$37*VLOOKUP('Opreating Cashflow (2)'!$A13,Data!$A$38:$B$41,2,0)/1000 -> -1492.5 | C13: =(+B13*(2.5%/4))+B13 -> -1501.8281 | D13: =(+C13*(2.5%/4))+C13 -> -1511.2146 | E13: =(+D13*(2.5%/4))+D13 -> -1520.6596 | F13: =(+E13*(2.5%/4))+E13 -> -1530.1638 | G13: =(+F13*(2.5%/4))+F13 -> -1539.7273 | H13: =(+G13*(2.5%/4))+G13 -> -1549.3506 | I13: =(+H13*(2.5%/4))+H13 -> -1559.034 | J13: =(+I13*(2.5%/4))+I13 -> -1568.778 | ... U13: =(+T13*(2.5%/4))+T13 -> -1680.0659
A14: Repairs & Maintenance | B14: =-Data!$B$37*VLOOKUP('Opreating Cashflow (2)'!$A14,Data!$A$38:$B$41,2,0)/1000 -> -1194 | C14: =(+B14*(2.5%/4))+B14 -> -1201.4625 | D14: =(+C14*(2.5%/4))+C14 -> -1208.9716 | E14: =(+D14*(2.5%/4))+D14 -> -1216.5277 | F14: =(+E14*(2.5%/4))+E14 -> -1224.131 | G14: =(+F14*(2.5%/4))+F14 -> -1231.7818 | H14: =(+G14*(2.5%/4))+G14 -> -1239.4805 | I14: =(+H14*(2.5%/4))+H14 -> -1247.2272 | J14: =(+I14*(2.5%/4))+I14 -> -1255.0224 | ... U14: =(+T14*(2.5%/4))+T14 -> -1344.0527
A15: Other opex | B15: =-Data!$B$37*VLOOKUP('Opreating Cashflow (2)'!$A15,Data!$A$38:$B$41,2,0)/1000 -> -597 | C15: =(+B15*(2.5%/4))+B15 -> -600.73125 | D15: =(+C15*(2.5%/4))+C15 -> -604.48582 | E15: =(+D15*(2.5%/4))+D15 -> -608.26386 | F15: =(+E15*(2.5%/4))+E15 -> -612.06551 | G15: =(+F15*(2.5%/4))+F15 -> -615.89092 | H15: =(+G15*(2.5%/4))+G15 -> -619.74023 | I15: =(+H15*(2.5%/4))+H15 -> -623.61361 | J15: =(+I15*(2.5%/4))+I15 -> -627.51119 | ... U15: =(+T15*(2.5%/4))+T15 -> -672.02636
A16: TOTAL OPERATING EXPENDITURE | B16: =SUM(B12:B15) -> -5970 | C16: =SUM(C12:C15) -> -6007.3125 | D16: =SUM(D12:D15) -> -6044.8582 | E16: =SUM(E12:E15) -> -6082.6386 | F16: =SUM(F12:F15) -> -6120.6551 | G16: =SUM(G12:G15) -> -6158.9092 | H16: =SUM(H12:H15) -> -6197.4023 | I16: =SUM(I12:I15) -> -6236.1361 | ... U16: =SUM(U12:U15) -> -6720.2636
A18: Depreciation | B18: =-630000/1000 -> -630 | C18: =-630000/1000 -> -630 | D18: =-630000/1000 -> -630 | E18: =-630000/1000 -> -630 | F18: =-630000/1000 -> -630 | G18: =-630000/1000 -> -630 | H18: =-630000/1000 -> -630 | I18: =-630000/1000 -> -630 | ... U18: =-630000/1000 -> -630
A19: Borrowing Cost | B19: =-170000/1000 -> -170 | C19: =-170000/1000 -> -170 | D19: =-170000/1000 -> -170 | E19: =-170000/1000 -> -170 | F19: =-170000/1000 -> -170 | G19: =-170000/1000 -> -170 | H19: =-170000/1000 -> -170 | I19: =-170000/1000 -> -170 | ... U19: =-170000/1000 -> -170
A20: Total Non-Operating EXPENDITURE | B20: =+B18+B19 -> -800 | C20: =+C18+C19 -> -800 | D20: =+D18+D19 -> -800 | E20: =+E18+E19 -> -800 | F20: =+F18+F19 -> -800 | G20: =+G18+G19 -> -800 | H20: =+H18+H19 -> -800 | I20: =+I18+I19 -> -800 | ... U20: =+U18+U19 -> -800
A22: OPERATING SURPLUS | B22: =+B8+B16+B20 -> 1840 | C22: =+C8+C16+C20 -> 1802.6875 | D22: =+D8+D16+D20 -> 1765.1418 | E22: =+E8+E16+E20 -> 1727.3614 | F22: =+F8+F16+F20 -> 1689.3449 | G22: =+G8+G16+G20 -> 1651.0908 | H22: =+H8+H16+H20 -> 1612.5977 | I22: =+I8+I16+I20 -> 1573.8639 | ... U22: =+U8+U16+U20 -> 1089.7364
A25: CAPITAL INVESTMENTS
A26: New leisure centre enhancements | B26: =((-8820000/1000))*0.65 -> -5733 | C26: =((-8820000/1000))*0.25 -> -2205 | D26: =((-8820000/1000))*0.1 -> -882 | H26: -1000 | O26: -1000
A27: Health & Fitness (Small) | B27: =-490000/1000 -> -490 | H27: =+B27/2 -> -245 | O27: =+H27 -> -245
A28: Golf Centre | B28: =-100000/1000 -> -100 | H28: =+B28/2 -> -50 | O28: =+H28 -> -50
A29: Interim Facility Revenue | B29: =-200000/1000 -> -200 | H29: =+B29/2 -> -100 | O29: =+H29 -> -100
A30: TOTAL CAPITAL INVESTMENTS | B30: =SUM(B26:B29) -> -6523 | C30: =SUM(C26:C29) -> -2205 | D30: =SUM(D26:D29) -> -882 | E30: =SUM(E26:E29) -> 0 | F30: =SUM(F26:F29) -> 0 | G30: =SUM(G26:G29) -> 0 | H30: =SUM(H26:H29) -> -1395 | I30: =SUM(I26:I29) -> 0 | ... U30: =SUM(U26:U29) -> 0
